Workbook

Sheet ИТОГОВА ТАБЛИЦА
A2: ОПТИМИЗАЦИЯ ПАРАМЕТРОВ РАБОЧЕГО ХОДА
A4: № п/п | B4: Параметры управления | F4: Целевые показатели
B5: v | C5: s | D5: p | E5: t | F5: T | G5: OPEX | H5: Err износ РИ | I5: Err тепл РИ | J5: P (профиль, текстура поверхности)
A6: =Расчеты!A19 -> 1 | B6: =Расчеты!B19 -> 1 | C6: =Расчеты!C19 -> 400 | D6: =Расчеты!D19 -> 0.05 | E6: =Расчеты!E19 -> 0.03 | F6: =Расчеты!F19 -> 0.69 | G6: =Расчеты!G19 -> 12.64 | H6: =Расчеты!H19 -> 1.547 | ... J6: =Расчеты!J19 -> 0.024
A7: =Расчеты!A20 -> 2 | B7: =Расчеты!B20 -> 1 | C7: =Расчеты!C20 -> 400 | D7: =Расчеты!D20 -> 0.05 | E7: =Расчеты!E20 -> 0.05 | F7: =Расчеты!F20 -> 0.69 | G7: =Расчеты!G20 -> 12.64 | H7: =Расчеты!H20 -> 1.547 | ... J7: =Расчеты!J20 -> 0.024
A8: =Расчеты!A21 -> 3 | B8: =Расчеты!B21 -> 1 | C8: =Расчеты!C21 -> 400 | D8: =Расчеты!D21 -> 0.05 | E8: =Расчеты!E21 -> 0.07 | F8: =Расчеты!F21 -> 0.69 | G8: =Расчеты!G21 -> 12.64 | H8: =Расчеты!H21 -> 1.547 | ... J8: =Расчеты!J21 -> 0.024
A9: =Расчеты!A22 -> 4 | B9: =Расчеты!B22 -> 1 | C9: =Расчеты!C22 -> 400 | D9: =Расчеты!D22 -> 0.05 | E9: =Расчеты!E22 -> 0.09 | F9: =Расчеты!F22 -> 0.69 | G9: =Расчеты!G22 -> 12.64 | H9: =Расчеты!H22 -> 1.547 | ... J9: =Расчеты!J22 -> 0.024
A10: =Расчеты!A23 -> 5 | B10: =Расчеты!B23 -> 1 | C10: =Расчеты!C23 -> 400 | D10: =Расчеты!D23 -> 0.05 | E10: =Расчеты!E23 -> 0.11 | F10: =Расчеты!F23 -> 0.69 | G10: =Расчеты!G23 -> 12.64 | H10: =Расчеты!H23 -> 1.547 | ... J10: =Расчеты!J23 -> 0.024
A11: =Расчеты!A24 -> 6 | B11: =Расчеты!B24 -> 1 | C11: =Расчеты!C24 -> 400 | D11: =Расчеты!D24 -> 0.05 | E11: =Расчеты!E24 -> 0.13 | F11: =Расчеты!F24 -> 0.69 | G11: =Расчеты!G24 -> 12.64 | H11: =Расчеты!H24 -> 1.547 | ... J11: =Расчеты!J24 -> 0.024
A12: =Расчеты!A25 -> 7 | B12: =Расчеты!B25 -> 1 | C12: =Расчеты!C25 -> 400 | D12: =Расчеты!D25 -> 0.05 | E12: =Расчеты!E25 -> 0.15 | F12: =Расчеты!F25 -> 0.69 | G12: =Расчеты!G25 -> 12.41 | H12: =Расчеты!H25 -> 1.547 | ... J12: =Расчеты!J25 -> 0.024
A13: =Расчеты!A26 -> 8 | B13: =Расчеты!B26 -> 1 | C13: =Расчеты!C26 -> 400 | D13: =Расчеты!D26 -> 0.06 | E13: =Расчеты!E26 -> 0.03 | F13: =Расчеты!F26 -> 0.58 | G13: =Расчеты!G26 -> 10.7 | H13: =Расчеты!H26 -> 1.289 | ... J13: =Расчеты!J26 -> 0.03
A14: =Расчеты!A27 -> 9 | B14: =Расчеты!B27 -> 1 | C14: =Расчеты!C27 -> 400 | D14: =Расчеты!D27 -> 0.06 | E14: =Расчеты!E27 -> 0.05 | F14: =Расчеты!F27 -> 0.58 | G14: =Расчеты!G27 -> 10.7 | H14: =Расчеты!H27 -> 1.289 | ... J14: =Расчеты!J27 -> 0.03
A15: =Расчеты!A28 -> 10 | B15: =Расчеты!B28 -> 1 | C15: =Расчеты!C28 -> 400 | D15: =Расчеты!D28 -> 0.06 | E15: =Расчеты!E28 -> 0.07 | F15: =Расчеты!F28 -> 0.58 | G15: =Расчеты!G28 -> 10.7 | H15: =Расчеты!H28 -> 1.289 | ... J15: =Расчеты!J28 -> 0.03
A16: =Расчеты!A29 -> 11 | B16: =Расчеты!B29 -> 1 | C16: =Расчеты!C29 -> 400 | D16: =Расчеты!D29 -> 0.06 | E16: =Расчеты!E29 -> 0.09 | F16: =Расчеты!F29 -> 0.58 | G16: =Расчеты!G29 -> 10.7 | H16: =Расчеты!H29 -> 1.289 | ... J16: =Расчеты!J29 -> 0.03
A17: =Расчеты!A30 -> 12 | B17: =Расчеты!B30 -> 1 | C17: =Расчеты!C30 -> 400 | D17: =Расчеты!D30 -> 0.06 | E17: =Расчеты!E30 -> 0.11 | F17: =Расчеты!F30 -> 0.58 | G17: =Расчеты!G30 -> 10.7 | H17: =Расчеты!H30 -> 1.289 | ... J17: =Расчеты!J30 -> 0.03
... A887: =Расчеты!A900 -> 882 | B887: =Расчеты!B900 -> 7 | C887: =Расчеты!C900 -> 460 | D887: =Расчеты!D900 -> 0.1 | E887: =Расчеты!E900 -> 0.15 | F887: =Расчеты!F900 -> 0.3 | G887: =Расчеты!G900 -> 4.67 | H887: =Расчеты!H900 -> 0.774 | ... J887: =Расчеты!J900 -> 0.077

Sheet Расчеты
B2: КОНСТАНТЫ | K2: min | L2: max | M2: Δ
B3: Длина обр. пов | C3: L | D3: 55 | F3: Цена 1Квт эл | G3: Цэ | H3: 6.19 | J3: Скорость резания | K3: 400 | L3: 460 | M3: 10
B4: Диаметр заг | C4: Dзаг | D4: 80 | F4: коэф пот. Эл | G4: kN | H4: 1.1 | J4: Подача | K4: 0.05 | L4: 0.1 | M4: 0.01
B5: Относ. Износ | C5: U0 | D5: 3 | G5: kW | H5: 1.05 | J5: Глубина резания | K5: 0.03 | L5: 0.15 | M5: 0.02
B6: Стоиомсть н/ч рабочего | C6: Сн/ч | D6: 400 | F6: КПД эл.вд | G6: η | H6: 0.8
B7: Дол. з/п | C7: α | D7: 0.25 | F7: мощ. эл дв | G7: Ni | H7: 2000
B8: Соц отчисления | C8: β | D8: 0.32 | F8: Вел. затрат рем/обс | G8: Зрем/обс | H8: 80000
B9: Стоиомсть ТО | C9: С, mach | D9: 2300000 | F9: Размер партии | G9: N пар | H9: 80
B10: Срок пол исп ТО | C10: T, исп. Mach | D10: 5 | F10: Кол раб. час в год | G10: Т, раб.час/ год | H10: 1972
F11: Относ. Износ | G11: U0 | H11: 7
A15: ОПТИМИЗАЦИЯ ПАРАМЕТРОВ РАБОЧЕГО ХОДА (тонкое точение)
A17: № п/п | B17: Параметры управления | F17: Целевые показатели | M17: OPEX
B18: p | C18: v | D18: s | E18: t | F18: T, мин | G18: OPEX, руб | H18: Err износ РИ, мкм | I18: Err тепл РИ, мкм | J18: P (профиль, текстура поверхности) | M18: OPEX, зп | N18: OPEX, ам | O18: OPEX, эл | P18: OPEX, рем | Q18: n
A19: 1 | B19: 1 | C19: =K3 -> 400 | D19: =K4 -> 0.05 | E19: =K5 -> 0.03 | F19: =ROUND($D$3/(Q19*D19),2) -> 0.69 | G19: =ROUND(M19+N19+N34+P19,2) -> 12.64 | H19: =ROUND((3.14*$D$4*$D$3*$H$11*$H$9)/(100000000*D19),3) -> 1.547 | I19: =ROUND(5.21*POWER(C19,0.15)*POWER(D19,0.18)*POWER(E19,0.25),3) -> 3.106 | J19: =ROUND(0.12*POWER(C19,0.33)*POWER(D19,1.2)*POWER(B19,0.15),3) -> 0.024 | M19: =($D$6*F19*(1+$D$7)*(1+$D$8))/60 -> 7.59 | N19: =($D$9*F19)/(60*$D$10*$H$10) -> 2.6825558 | O19: =($H$3*$H$4*$H$5*$H$7*F19)/($H$6*60) -> 205.54669 | P19: =($H$8*F19)/($H$10*60) -> 0.46653144 | Q19: =ROUND((1000*C19)/(3.14*$D$4),0) -> 1592
A20: 2 | B20: =B19 -> 1 | C20: =C19 -> 400 | D20: =D19 -> 0.05 | E20: =E19+$M$5 -> 0.05 | F20: =ROUND($D$3/(Q20*D20),2) -> 0.69 | G20: =ROUND(M20+N20+N35+P20,2) -> 12.64 | H20: =ROUND((3.14*$D$4*$D$3*$H$11*$H$9)/(100000000*D20),3) -> 1.547 | I20: =ROUND(5.21*POWER(C20,0.15)*POWER(D20,0.18)*POWER(E20,0.25),3) -> 3.529 | J20: =ROUND(0.12*POWER(C20,0.33)*POWER(D20,1.2)*POWER(B20,0.15),3) -> 0.024 | M20: =($D$6*F20*(1+$D$7)*(1+$D$8))/60 -> 7.59 | N20: =($D$9*F20)/(60*$D$10*$H$10) -> 2.6825558 | O20: =($H$3*$H$4*$H$5*$H$7*F20)/($H$6*60) -> 205.54669 | P20: =($H$8*F20)/($H$10*60) -> 0.46653144 | Q20: =ROUND((1000*C20)/(3.14*$D$4),0) -> 1592
A21: 3 | B21: =B20 -> 1 | C21: =C20 -> 400 | D21: =D20 -> 0.05 | E21: =E20+$M$5 -> 0.07 | F21: =ROUND($D$3/(Q21*D21),2) -> 0.69 | G21: =ROUND(M21+N21+N36+P21,2) -> 12.64 | H21: =ROUND((3.14*$D$4*$D$3*$H$11*$H$9)/(100000000*D21),3) -> 1.547 | I21: =ROUND(5.21*POWER(C21,0.15)*POWER(D21,0.18)*POWER(E21,0.25),3) -> 3.839 | J21: =ROUND(0.12*POWER(C21,0.33)*POWER(D21,1.2)*POWER(B21,0.15),3) -> 0.024 | M21: =($D$6*F21*(1+$D$7)*(1+$D$8))/60 -> 7.59 | N21: =($D$9*F21)/(60*$D$10*$H$10) -> 2.6825558 | O21: =($H$3*$H$4*$H$5*$H$7*F21)/($H$6*60) -> 205.54669 | P21: =($H$8*F21)/($H$10*60) -> 0.46653144 | Q21: =ROUND((1000*C21)/(3.14*$D$4),0) -> 1592
A22: 4 | B22: =B21 -> 1 | C22: =C21 -> 400 | D22: =D21 -> 0.05 | E22: =E21+$M$5 -> 0.09 | F22: =ROUND($D$3/(Q22*D22),2) -> 0.69 | G22: =ROUND(M22+N22+N37+P22,2) -> 12.64 | H22: =ROUND((3.14*$D$4*$D$3*$H$11*$H$9)/(100000000*D22),3) -> 1.547 | I22: =ROUND(5.21*POWER(C22,0.15)*POWER(D22,0.18)*POWER(E22,0.25),3) -> 4.088 | J22: =ROUND(0.12*POWER(C22,0.33)*POWER(D22,1.2)*POWER(B22,0.15),3) -> 0.024 | M22: =($D$6*F22*(1+$D$7)*(1+$D$8))/60 -> 7.59 | N22: =($D$9*F22)/(60*$D$10*$H$10) -> 2.6825558 | O22: =($H$3*$H$4*$H$5*$H$7*F22)/($H$6*60) -> 205.54669 | P22: =($H$8*F22)/($H$10*60) -> 0.46653144 | Q22: =ROUND((1000*C22)/(3.14*$D$4),0) -> 1592
A23: 5 | B23: =B22 -> 1 | C23: =C22 -> 400 | D23: =D22 -> 0.05 | E23: =E22+$M$5 -> 0.11 | F23: =ROUND($D$3/(Q23*D23),2) -> 0.69 | G23: =ROUND(M23+N23+N38+P23,2) -> 12.64 | H23: =ROUND((3.14*$D$4*$D$3*$H$11*$H$9)/(100000000*D23),3) -> 1.547 | I23: =ROUND(5.21*POWER(C23,0.15)*POWER(D23,0.18)*POWER(E23,0.25),3) -> 4.298 | J23: =ROUND(0.12*POWER(C23,0.33)*POWER(D23,1.2)*POWER(B23,0.15),3) -> 0.024 | M23: =($D$6*F23*(1+$D$7)*(1+$D$8))/60 -> 7.59 | N23: =($D$9*F23)/(60*$D$10*$H$10) -> 2.6825558 | O23: =($H$3*$H$4*$H$5*$H$7*F23)/($H$6*60) -> 205.54669 | P23: =($H$8*F23)/($H$10*60) -> 0.46653144 | Q23: =ROUND((1000*C23)/(3.14*$D$4),0) -> 1592
A24: 6 | B24: =B23 -> 1 | C24: =C23 -> 400 | D24: =D23 -> 0.05 | E24: =E23+$M$5 -> 0.13 | F24: =ROUND($D$3/(Q24*D24),2) -> 0.69 | G24: =ROUND(M24+N24+N39+P24,2) -> 12.64 | H24: =ROUND((3.14*$D$4*$D$3*$H$11*$H$9)/(100000000*D24),3) -> 1.547 | I24: =ROUND(5.21*POWER(C24,0.15)*POWER(D24,0.18)*POWER(E24,0.25),3) -> 4.482 | J24: =ROUND(0.12*POWER(C24,0.33)*POWER(D24,1.2)*POWER(B24,0.15),3) -> 0.024 | M24: =($D$6*F24*(1+$D$7)*(1+$D$8))/60 -> 7.59 | N24: =($D$9*F24)/(60*$D$10*$H$10) -> 2.6825558 | O24: =($H$3*$H$4*$H$5*$H$7*F24)/($H$6*60) -> 205.54669 | P24: =($H$8*F24)/($H$10*60) -> 0.46653144 | Q24: =ROUND((1000*C24)/(3.14*$D$4),0) -> 1592
A25: 7 | B25: =B24 -> 1 | C25: =C24 -> 400 | D25: =D24 -> 0.05 | E25: =E24+$M$5 -> 0.15 | F25: =ROUND($D$3/(Q25*D25),2) -> 0.69 | G25: =ROUND(M25+N25+N40+P25,2) -> 12.41 | H25: =ROUND((3.14*$D$4*$D$3*$H$11*$H$9)/(100000000*D25),3) -> 1.547 | I25: =ROUND(5.21*POWER(C25,0.15)*POWER(D25,0.18)*POWER(E25,0.25),3) -> 4.645 | J25: =ROUND(0.12*POWER(C25,0.33)*POWER(D25,1.2)*POWER(B25,0.15),3) -> 0.024 | M25: =($D$6*F25*(1+$D$7)*(1+$D$8))/60 -> 7.59 | N25: =($D$9*F25)/(60*$D$10*$H$10) -> 2.6825558 | O25: =($H$3*$H$4*$H$5*$H$7*F25)/($H$6*60) -> 205.54669 | P25: =($H$8*F25)/($H$10*60) -> 0.46653144 | Q25: =ROUND((1000*C25)/(3.14*$D$4),0) -> 1592
A26: 8 | B26: =B25 -> 1 | C26: =C25 -> 400 | D26: =D19+$M$4 -> 0.06 | E26: =E19 -> 0.03 | F26: =ROUND($D$3/(Q26*D26),2) -> 0.58 | G26: =ROUND(M26+N26+N41+P26,2) -> 10.7 | H26: =ROUND((3.14*$D$4*$D$3*$H$11*$H$9)/(100000000*D26),3) -> 1.289 | I26: =ROUND(5.21*POWER(C26,0.15)*POWER(D26,0.18)*POWER(E26,0.25),3) -> 3.21 | J26: =ROUND(0.12*POWER(C26,0.33)*POWER(D26,1.2)*POWER(B26,0.15),3) -> 0.03 | M26: =($D$6*F26*(1+$D$7)*(1+$D$8))/60 -> 6.38 | N26: =($D$9*F26)/(60*$D$10*$H$10) -> 2.254902 | O26: =($H$3*$H$4*$H$5*$H$7*F26)/($H$6*60) -> 172.77838 | P26: =($H$8*F26)/($H$10*60) -> 0.39215686 | Q26: =ROUND((1000*C26)/(3.14*$D$4),0) -> 1592
A27: 9 | B27: =B26 -> 1 | C27: =C26 -> 400 | D27: =D20+$M$4 -> 0.06 | E27: =E20 -> 0.05 | F27: =ROUND($D$3/(Q27*D27),2) -> 0.58 | G27: =ROUND(M27+N27+N42+P27,2) -> 10.7 | H27: =ROUND((3.14*$D$4*$D$3*$H$11*$H$9)/(100000000*D27),3) -> 1.289 | I27: =ROUND(5.21*POWER(C27,0.15)*POWER(D27,0.18)*POWER(E27,0.25),3) -> 3.647 | J27: =ROUND(0.12*POWER(C27,0.33)*POWER(D27,1.2)*POWER(B27,0.15),3) -> 0.03 | M27: =($D$6*F27*(1+$D$7)*(1+$D$8))/60 -> 6.38 | N27: =($D$9*F27)/(60*$D$10*$H$10) -> 2.254902 | O27: =($H$3*$H$4*$H$5*$H$7*F27)/($H$6*60) -> 172.77838 | P27: =($H$8*F27)/($H$10*60) -> 0.39215686 | Q27: =ROUND((1000*C27)/(3.14*$D$4),0) -> 1592
A28: 10 | B28: =B27 -> 1 | C28: =C27 -> 400 | D28: =D21+$M$4 -> 0.06 | E28: =E21 -> 0.07 | F28: =ROUND($D$3/(Q28*D28),2) -> 0.58 | G28: =ROUND(M28+N28+N43+P28,2) -> 10.7 | H28: =ROUND((3.14*$D$4*$D$3*$H$11*$H$9)/(100000000*D28),3) -> 1.289 | I28: =ROUND(5.21*POWER(C28,0.15)*POWER(D28,0.18)*POWER(E28,0.25),3) -> 3.967 | J28: =ROUND(0.12*POWER(C28,0.33)*POWER(D28,1.2)*POWER(B28,0.15),3) -> 0.03 | M28: =($D$6*F28*(1+$D$7)*(1+$D$8))/60 -> 6.38 | N28: =($D$9*F28)/(60*$D$10*$H$10) -> 2.254902 | O28: =($H$3*$H$4*$H$5*$H$7*F28)/($H$6*60) -> 172.77838 | P28: =($H$8*F28)/($H$10*60) -> 0.39215686 | Q28: =ROUND((1000*C28)/(3.14*$D$4),0) -> 1592
A29: 11 | B29: =B28 -> 1 | C29: =C28 -> 400 | D29: =D22+$M$4 -> 0.06 | E29: =E22 -> 0.09 | F29: =ROUND($D$3/(Q29*D29),2) -> 0.58 | G29: =ROUND(M29+N29+N44+P29,2) -> 10.7 | H29: =ROUND((3.14*$D$4*$D$3*$H$11*$H$9)/(100000000*D29),3) -> 1.289 | I29: =ROUND(5.21*POWER(C29,0.15)*POWER(D29,0.18)*POWER(E29,0.25),3) -> 4.224 | J29: =ROUND(0.12*POWER(C29,0.33)*POWER(D29,1.2)*POWER(B29,0.15),3) -> 0.03 | M29: =($D$6*F29*(1+$D$7)*(1+$D$8))/60 -> 6.38 | N29: =($D$9*F29)/(60*$D$10*$H$10) -> 2.254902 | O29: =($H$3*$H$4*$H$5*$H$7*F29)/($H$6*60) -> 172.77838 | P29: =($H$8*F29)/($H$10*60) -> 0.39215686 | Q29: =ROUND((1000*C29)/(3.14*$D$4),0) -> 1592
A30: 12 | B30: =B29 -> 1 | C30: =C29 -> 400 | D30: =D23+$M$4 -> 0.06 | E30: =E23 -> 0.11 | F30: =ROUND($D$3/(Q30*D30),2) -> 0.58 | G30: =ROUND(M30+N30+N45+P30,2) -> 10.7 | H30: =ROUND((3.14*$D$4*$D$3*$H$11*$H$9)/(100000000*D30),3) -> 1.289 | I30: =ROUND(5.21*POWER(C30,0.15)*POWER(D30,0.18)*POWER(E30,0.25),3) -> 4.442 | J30: =ROUND(0.12*POWER(C30,0.33)*POWER(D30,1.2)*POWER(B30,0.15),3) -> 0.03 | M30: =($D$6*F30*(1+$D$7)*(1+$D$8))/60 -> 6.38 | N30: =($D$9*F30)/(60*$D$10*$H$10) -> 2.254902 | O30: =($H$3*$H$4*$H$5*$H$7*F30)/($H$6*60) -> 172.77838 | P30: =($H$8*F30)/($H$10*60) -> 0.39215686 | Q30: =ROUND((1000*C30)/(3.14*$D$4),0) -> 1592
A31: 13 | B31: =B30 -> 1 | C31: =C30 -> 400 | D31: =D24+$M$4 -> 0.06 | E31: =E24 -> 0.13 | F31: =ROUND($D$3/(Q31*D31),2) -> 0.58 | G31: =ROUND(M31+N31+N46+P31,2) -> 10.7 | H31: =ROUND((3.14*$D$4*$D$3*$H$11*$H$9)/(100000000*D31),3) -> 1.289 | I31: =ROUND(5.21*POWER(C31,0.15)*POWER(D31,0.18)*POWER(E31,0.25),3) -> 4.631 | J31: =ROUND(0.12*POWER(C31,0.33)*POWER(D31,1.2)*POWER(B31,0.15),3) -> 0.03 | M31: =($D$6*F31*(1+$D$7)*(1+$D$8))/60 -> 6.38 | N31: =($D$9*F31)/(60*$D$10*$H$10) -> 2.254902 | O31: =($H$3*$H$4*$H$5*$H$7*F31)/($H$6*60) -> 172.77838 | P31: =($H$8*F31)/($H$10*60) -> 0.39215686 | Q31: =ROUND((1000*C31)/(3.14*$D$4),0) -> 1592
A32: 14 | B32: =B31 -> 1 | C32: =C31 -> 400 | D32: =D25+$M$4 -> 0.06 | E32: =E25 -> 0.15 | F32: =ROUND($D$3/(Q32*D32),2) -> 0.58 | G32: =ROUND(M32+N32+N47+P32,2) -> 10.5 | H32: =ROUND((3.14*$D$4*$D$3*$H$11*$H$9)/(100000000*D32),3) -> 1.289 | I32: =ROUND(5.21*POWER(C32,0.15)*POWER(D32,0.18)*POWER(E32,0.25),3) -> 4.8 | J32: =ROUND(0.12*POWER(C32,0.33)*POWER(D32,1.2)*POWER(B32,0.15),3) -> 0.03 | M32: =($D$6*F32*(1+$D$7)*(1+$D$8))/60 -> 6.38 | N32: =($D$9*F32)/(60*$D$10*$H$10) -> 2.254902 | O32: =($H$3*$H$4*$H$5*$H$7*F32)/($H$6*60) -> 172.77838 | P32: =($H$8*F32)/($H$10*60) -> 0.39215686 | Q32: =ROUND((1000*C32)/(3.14*$D$4),0) -> 1592
A33: 15 | B33: =B32 -> 1 | C33: =C32 -> 400 | D33: =D26+$M$4 -> 0.07 | E33: =E26 -> 0.03 | F33: =ROUND($D$3/(Q33*D33),2) -> 0.49 | G33: =ROUND(M33+N33+N48+P33,2) -> 9.1 | H33: =ROUND((3.14*$D$4*$D$3*$H$11*$H$9)/(100000000*D33),3) -> 1.105 | I33: =ROUND(5.21*POWER(C33,0.15)*POWER(D33,0.18)*POWER(E33,0.25),3) -> 3.3 | J33: =ROUND(0.12*POWER(C33,0.33)*POWER(D33,1.2)*POWER(B33,0.15),3) -> 0.036 | M33: =($D$6*F33*(1+$D$7)*(1+$D$8))/60 -> 5.39 | N33: =($D$9*F33)/(60*$D$10*$H$10) -> 1.9050034 | O33: =($H$3*$H$4*$H$5*$H$7*F33)/($H$6*60) -> 145.96794 | P33: =($H$8*F33)/($H$10*60) -> 0.33130494 | Q33: =ROUND((1000*C33)/(3.14*$D$4),0) -> 1592
A34: 16 | B34: =B33 -> 1 | C34: =C33 -> 400 | D34: =D27+$M$4 -> 0.07 | E34: =E27 -> 0.05 | F34: =ROUND($D$3/(Q34*D34),2) -> 0.49 | G34: =ROUND(M34+N34+N49+P34,2) -> 9.1 | H34: =ROUND((3.14*$D$4*$D$3*$H$11*$H$9)/(100000000*D34),3) -> 1.105 | I34: =ROUND(5.21*POWER(C34,0.15)*POWER(D34,0.18)*POWER(E34,0.25),3) -> 3.75 | J34: =ROUND(0.12*POWER(C34,0.33)*POWER(D34,1.2)*POWER(B34,0.15),3) -> 0.036 | M34: =($D$6*F34*(1+$D$7)*(1+$D$8))/60 -> 5.39 | N34: =($D$9*F34)/(60*$D$10*$H$10) -> 1.9050034 | O34: =($H$3*$H$4*$H$5*$H$7*F34)/($H$6*60) -> 145.96794 | P34: =($H$8*F34)/($H$10*60) -> 0.33130494 | Q34: =ROUND((1000*C34)/(3.14*$D$4),0) -> 1592
A35: 17 | B35: =B34 -> 1 | C35: =C34 -> 400 | D35: =D28+$M$4 -> 0.07 | E35: =E28 -> 0.07 | F35: =ROUND($D$3/(Q35*D35),2) -> 0.49 | G35: =ROUND(M35+N35+N50+P35,2) -> 9.1 | H35: =ROUND((3.14*$D$4*$D$3*$H$11*$H$9)/(100000000*D35),3) -> 1.105 | I35: =ROUND(5.21*POWER(C35,0.15)*POWER(D35,0.18)*POWER(E35,0.25),3) -> 4.079 | J35: =ROUND(0.12*POWER(C35,0.33)*POWER(D35,1.2)*POWER(B35,0.15),3) -> 0.036 | M35: =($D$6*F35*(1+$D$7)*(1+$D$8))/60 -> 5.39 | N35: =($D$9*F35)/(60*$D$10*$H$10) -> 1.9050034 | O35: =($H$3*$H$4*$H$5*$H$7*F35)/($H$6*60) -> 145.96794 | P35: =($H$8*F35)/($H$10*60) -> 0.33130494 | Q35: =ROUND((1000*C35)/(3.14*$D$4),0) -> 1592
A36: 18 | B36: =B35 -> 1 | C36: =C35 -> 400 | D36: =D29+$M$4 -> 0.07 | E36: =E29 -> 0.09 | F36: =ROUND($D$3/(Q36*D36),2) -> 0.49 | G36: =ROUND(M36+N36+N51+P36,2) -> 9.1 | H36: =ROUND((3.14*$D$4*$D$3*$H$11*$H$9)/(100000000*D36),3) -> 1.105 | I36: =ROUND(5.21*POWER(C36,0.15)*POWER(D36,0.18)*POWER(E36,0.25),3) -> 4.343 | J36: =ROUND(0.12*POWER(C36,0.33)*POWER(D36,1.2)*POWER(B36,0.15),3) -> 0.036 | M36: =($D$6*F36*(1+$D$7)*(1+$D$8))/60 -> 5.39 | N36: =($D$9*F36)/(60*$D$10*$H$10) -> 1.9050034 | O36: =($H$3*$H$4*$H$5*$H$7*F36)/($H$6*60) -> 145.96794 | P36: =($H$8*F36)/($H$10*60) -> 0.33130494 | Q36: =ROUND((1000*C36)/(3.14*$D$4),0) -> 1592
A37: 19 | B37: =B36 -> 1 | C37: =C36 -> 400 | D37: =D30+$M$4 -> 0.07 | E37: =E30 -> 0.11 | F37: =ROUND($D$3/(Q37*D37),2) -> 0.49 | G37: =ROUND(M37+N37+N52+P37,2) -> 9.1 | H37: =ROUND((3.14*$D$4*$D$3*$H$11*$H$9)/(100000000*D37),3) -> 1.105 | I37: =ROUND(5.21*POWER(C37,0.15)*POWER(D37,0.18)*POWER(E37,0.25),3) -> 4.567 | J37: =ROUND(0.12*POWER(C37,0.33)*POWER(D37,1.2)*POWER(B37,0.15),3) -> 0.036 | M37: =($D$6*F37*(1+$D$7)*(1+$D$8))/60 -> 5.39 | N37: =($D$9*F37)/(60*$D$10*$H$10) -> 1.9050034 | O37: =($H$3*$H$4*$H$5*$H$7*F37)/($H$6*60) -> 145.96794 | P37: =($H$8*F37)/($H$10*60) -> 0.33130494 | Q37: =ROUND((1000*C37)/(3.14*$D$4),0) -> 1592
... A60: 42 | B60: =B59 -> 1 | C60: =C59 -> 400 | D60: =D53+$M$4 -> 0.1 | E60: =E53 -> 0.15 | F60: =ROUND($D$3/(Q60*D60),2) -> 0.35 | G60: =ROUND(M60+N60+N75+P60,2) -> 7.31 | H60: =ROUND((3.14*$D$4*$D$3*$H$11*$H$9)/(100000000*D60),3) -> 0.774 | I60: =ROUND(5.21*POWER(C60,0.15)*POWER(D60,0.18)*POWER(E60,0.25),3) -> 5.262 | J60: =ROUND(0.12*POWER(C60,0.33)*POWER(D60,1.2)*POWER(B60,0.15),3) -> 0.055 | M60: =($D$6*F60*(1+$D$7)*(1+$D$8))/60 -> 3.85 | N60: =($D$9*F60)/(60*$D$10*$H$10) -> 1.3607167 | O60: =($H$3*$H$4*$H$5*$H$7*F60)/($H$6*60) -> 104.26281 | P60: =($H$8*F60)/($H$10*60) -> 0.23664638 | Q60: =ROUND((1000*C60)/(3.14*$D$4),0) -> 1592
A61: 43 | B61: =B60 -> 1 | C61: =C19+$M$3 -> 410 | D61: =D19 -> 0.05 | E61: =E19 -> 0.03 | F61: =ROUND($D$3/(Q61*D61),2) -> 0.67 | G61: =ROUND(M61+N61+N76+P61,2) -> 12.29 | H61: =ROUND((3.14*$D$4*$D$3*$H$11*$H$9)/(100000000*D61),3) -> 1.547 | I61: =ROUND(5.21*POWER(C61,0.15)*POWER(D61,0.18)*POWER(E61,0.25),3) -> 3.118 | J61: =ROUND(0.12*POWER(C61,0.33)*POWER(D61,1.2)*POWER(B61,0.15),3) -> 0.024 | M61: =($D$6*F61*(1+$D$7)*(1+$D$8))/60 -> 7.37 | N61: =($D$9*F61)/(60*$D$10*$H$10) -> 2.6048005 | O61: =($H$3*$H$4*$H$5*$H$7*F61)/($H$6*60) -> 199.58881 | P61: =($H$8*F61)/($H$10*60) -> 0.45300879 | Q61: =ROUND((1000*C61)/(3.14*$D$4),0) -> 1632
A62: 44 | B62: =B61 -> 1 | C62: =C20+$M$3 -> 410 | D62: =D20 -> 0.05 | E62: =E20 -> 0.05 | F62: =ROUND($D$3/(Q62*D62),2) -> 0.67 | G62: =ROUND(M62+N62+N77+P62,2) -> 12.29 | H62: =ROUND((3.14*$D$4*$D$3*$H$11*$H$9)/(100000000*D62),3) -> 1.547 | I62: =ROUND(5.21*POWER(C62,0.15)*POWER(D62,0.18)*POWER(E62,0.25),3) -> 3.543 | J62: =ROUND(0.12*POWER(C62,0.33)*POWER(D62,1.2)*POWER(B62,0.15),3) -> 0.024 | M62: =($D$6*F62*(1+$D$7)*(1+$D$8))/60 -> 7.37 | N62: =($D$9*F62)/(60*$D$10*$H$10) -> 2.6048005 | O62: =($H$3*$H$4*$H$5*$H$7*F62)/($H$6*60) -> 199.58881 | P62: =($H$8*F62)/($H$10*60) -> 0.45300879 | Q62: =ROUND((1000*C62)/(3.14*$D$4),0) -> 1632
A63: 45 | B63: =B62 -> 1 | C63: =C21+$M$3 -> 410 | D63: =D21 -> 0.05 | E63: =E21 -> 0.07 | F63: =ROUND($D$3/(Q63*D63),2) -> 0.67 | G63: =ROUND(M63+N63+N78+P63,2) -> 12.29 | H63: =ROUND((3.14*$D$4*$D$3*$H$11*$H$9)/(100000000*D63),3) -> 1.547 | I63: =ROUND(5.21*POWER(C63,0.15)*POWER(D63,0.18)*POWER(E63,0.25),3) -> 3.853 | J63: =ROUND(0.12*POWER(C63,0.33)*POWER(D63,1.2)*POWER(B63,0.15),3) -> 0.024 | M63: =($D$6*F63*(1+$D$7)*(1+$D$8))/60 -> 7.37 | N63: =($D$9*F63)/(60*$D$10*$H$10) -> 2.6048005 | O63: =($H$3*$H$4*$H$5*$H$7*F63)/($H$6*60) -> 199.58881 | P63: =($H$8*F63)/($H$10*60) -> 0.45300879 | Q63: =ROUND((1000*C63)/(3.14*$D$4),0) -> 1632
A64: 46 | B64: =B63 -> 1 | C64: =C22+$M$3 -> 410 | D64: =D22 -> 0.05 | E64: =E22 -> 0.09 | F64: =ROUND($D$3/(Q64*D64),2) -> 0.67 | G64: =ROUND(M64+N64+N79+P64,2) -> 12.29 | H64: =ROUND((3.14*$D$4*$D$3*$H$11*$H$9)/(100000000*D64),3) -> 1.547 | I64: =ROUND(5.21*POWER(C64,0.15)*POWER(D64,0.18)*POWER(E64,0.25),3) -> 4.103 | J64: =ROUND(0.12*POWER(C64,0.33)*POWER(D64,1.2)*POWER(B64,0.15),3) -> 0.024 | M64: =($D$6*F64*(1+$D$7)*(1+$D$8))/60 -> 7.37 | N64: =($D$9*F64)/(60*$D$10*$H$10) -> 2.6048005 | O64: =($H$3*$H$4*$H$5*$H$7*F64)/($H$6*60) -> 199.58881 | P64: =($H$8*F64)/($H$10*60) -> 0.45300879 | Q64: =ROUND((1000*C64)/(3.14*$D$4),0) -> 1632
A65: 47 | B65: =B64 -> 1 | C65: =C23+$M$3 -> 410 | D65: =D23 -> 0.05 | E65: =E23 -> 0.11 | F65: =ROUND($D$3/(Q65*D65),2) -> 0.67 | G65: =ROUND(M65+N65+N80+P65,2) -> 12.29 | H65: =ROUND((3.14*$D$4*$D$3*$H$11*$H$9)/(100000000*D65),3) -> 1.547 | I65: =ROUND(5.21*POWER(C65,0.15)*POWER(D65,0.18)*POWER(E65,0.25),3) -> 4.314 | J65: =ROUND(0.12*POWER(C65,0.33)*POWER(D65,1.2)*POWER(B65,0.15),3) -> 0.024 | M65: =($D$6*F65*(1+$D$7)*(1+$D$8))/60 -> 7.37 | N65: =($D$9*F65)/(60*$D$10*$H$10) -> 2.6048005 | O65: =($H$3*$H$4*$H$5*$H$7*F65)/($H$6*60) -> 199.58881 | P65: =($H$8*F65)/($H$10*60) -> 0.45300879 | Q65: =ROUND((1000*C65)/(3.14*$D$4),0) -> 1632
A66: 48 | B66: =B65 -> 1 | C66: =C24+$M$3 -> 410 | D66: =D24 -> 0.05 | E66: =E24 -> 0.13 | F66: =ROUND($D$3/(Q66*D66),2) -> 0.67 | G66: =ROUND(M66+N66+N81+P66,2) -> 12.29 | H66: =ROUND((3.14*$D$4*$D$3*$H$11*$H$9)/(100000000*D66),3) -> 1.547 | I66: =ROUND(5.21*POWER(C66,0.15)*POWER(D66,0.18)*POWER(E66,0.25),3) -> 4.498 | J66: =ROUND(0.12*POWER(C66,0.33)*POWER(D66,1.2)*POWER(B66,0.15),3) -> 0.024 | M66: =($D$6*F66*(1+$D$7)*(1+$D$8))/60 -> 7.37 | N66: =($D$9*F66)/(60*$D$10*$H$10) -> 2.6048005 | O66: =($H$3*$H$4*$H$5*$H$7*F66)/($H$6*60) -> 199.58881 | P66: =($H$8*F66)/($H$10*60) -> 0.45300879 | Q66: =ROUND((1000*C66)/(3.14*$D$4),0) -> 1632
A67: 49 | B67: =B66 -> 1 | C67: =C25+$M$3 -> 410 | D67: =D25 -> 0.05 | E67: =E25 -> 0.15 | F67: =ROUND($D$3/(Q67*D67),2) -> 0.67 | G67: =ROUND(M67+N67+N82+P67,2) -> 12.06 | H67: =ROUND((3.14*$D$4*$D$3*$H$11*$H$9)/(100000000*D67),3) -> 1.547 | I67: =ROUND(5.21*POWER(C67,0.15)*POWER(D67,0.18)*POWER(E67,0.25),3) -> 4.662 | J67: =ROUND(0.12*POWER(C67,0.33)*POWER(D67,1.2)*POWER(B67,0.15),3) -> 0.024 | M67: =($D$6*F67*(1+$D$7)*(1+$D$8))/60 -> 7.37 | N67: =($D$9*F67)/(60*$D$10*$H$10) -> 2.6048005 | O67: =($H$3*$H$4*$H$5*$H$7*F67)/($H$6*60) -> 199.58881 | P67: =($H$8*F67)/($H$10*60) -> 0.45300879 | Q67: =ROUND((1000*C67)/(3.14*$D$4),0) -> 1632
...
